Workbook

Sheet Instructions
B6: 📝 Instructions to Use the Excel Tax Calculator
B8: 1. Start with Basic Details
B9: Enter your Name, Age, Residential Status, and your Parents' Age (if applicable).
B11: 2. Input in Highlighted Cells
B12: Fill values only in the orange shade-coloured cells where applicable. Ensure all other input cells remain at zero if not relevant.
B14: 3. Follow On-Cell Instructions
B15: When you click any input cell, tooltips will guide you with what needs to be entered — making it easier and error-free.
B17: 4. Pay Attention to Regime-Based Differences
B18: In a few cases, input rules vary for the Old and New Tax Regimes. You may need to enter values separately for each regime as per instructions shown.
B20: 5. Use the HRA Calculator Sheet
B21: For accurate House Rent Allowance (HRA) exemption, use the HRA Calculator sheet and input the eligible exemption in the main calculator.
B23: 6. Review the Tax Summary
... B27: Separate sheets are provided to show tax benefits under the Old Regime and New Regime — updated as per Budget 2025.

Sheet Tax Calculator FY 2025-26
B2: Income Tax Calculator - FY 2025-26 (AY 2026-27) (Return to be filed between 1st Apr 2026 to 31st Dec 2026)
B3: Updated the calculator considering marginal relief under the new tax regime & Budget 2025
B5: TAX PAYER NAME: | C5: SAI PRATAP KOPPARAPU | G5: Fill the data only in this coloured cells
B6: TAX PAYER AGE: | C6: 35 | E6: Years
B7: RESIDENTIAL STATUS: | C7: RESIDENT
B8: PARENT'S AGE: | C8: 65 | E8: Years
B10: INCOME TAX CALCULATOR FOR FY 2025-26 (AY 2026-27) | G10: TAX CALCULATION AS PER OLD TAX REGIME | N10: TAX CALCULATION AS PER NEW TAX REGIME
B11: (for resident and non-resident individuals) | G11: Income Tax Slab | I11: Tax rate | J11: Slab Value | K11: Balance | L11: Tax | N11: (Marginal relief has been considered under the new tax regime)
B12: Particulars | C12: Actual | D12: Old Regime | E12: New Regime | G12: =+IF(C6<60,"Upto 2,50,000",IF(C6<80,"Upto 3,00,000","Upto 5,00,000")) -> Upto 2,50,000 | I12: 0 | J12: =+IF(C6<60,(IF(D37>250000,250000,D37)),IF(C6<80,(IF(D37>300000,300000,D37)),(IF(D37>500000,500000,D37)))) -> 250000 | K12: =+IF(D37>250000,D37-J12,0) -> 1640532 | L12: 0 | N12: Income Tax Slab | P12: Tax rate | Q12: Slab Value | R12: Balance | S12: Tax
B13: Gross Salary | C13: 2500000 | D13: =+C13 -> 2500000 | E13: =+C13 -> 2500000 | G13: =+IF(C6<60,"2,50,001 - 5,00,000",IF(C6<80,"3,00,000 - 5,00,000",0)) -> 2,50,001 - 5,00,000 | I13: =+IF(C6<80,"5%",0) -> 5% | J13: =+IF(C6<60,(IF(K12>250000,250000,K12)),IF(C6<80,(IF(K12>200000,200000,K12)),0)) -> 250000 | K13: =+IF(C6<60,IF(K12>250000,K12-250000,0),IF(C6<80,IF(K12>200000,K12-200000,0),0)) -> 1390532 | L13: =+J13*I13 -> 12500 | N13: Upto 4,00,000 | P13: 0 | Q13: =+IF(E37>400000,400000,E37) -> 400000 | R13: =+IF(E37>400000,E37-400000,0) -> 1985000 | S13: =+Q13*P13 -> 0
B14: Less: Standard Deduction | D14: =+IF(C13>50000,50000,C13) -> 50000 | E14: =+IF(C13>75000,75000,C13) -> 75000 | G14: 5,00,001 - 10,00,000 | I14: 0.2 | J14: =+IF(C6<60,IF(K13>500000,500000,K13),IF(C6<80,IF(K13>500000,500000,K13),IF(K12>500000,500000,K12))) -> 500000 | K14: =+IF(C6<60,IF(K13>500000,K13-500000,0),IF(C6<80,IF(K13>500000,K13-500000,0),IF(K12>500000,K12-500000,0))) -> 890532 | L14: =+J14*I14 -> 100000 | N14: 4,00,001- 8,00,000 | P14: 0.05 | Q14: =+IF(R13>400000,400000,R13) -> 400000 | R14: =+IF(R13>400000,R13-400000,0) -> 1585000 | S14: =+Q14*P14 -> 20000
B15: Net Salary | D15: =+D13-D14 -> 2450000 | E15: =+E13-E14 -> 2425000 | G15: Above 10,00,000 | I15: 0.3 | J15: =+IF(K14>0,K14,0) -> 890532 | L15: =+J15*I15 -> 267159.6 | N15: 8,00,001 - 12,00,000 | P15: 0.1 | Q15: =+IF(R14>400000,400000,R14) -> 400000 | R15: =+IF(R14>400000,R14-400000,0) -> 1185000 | S15: =+Q15*P15 -> 40000
B16: Income from savings bank interest | C16: 15000 | D16: =+C16 -> 15000 | E16: =+C16 -> 15000 | G16: Tax on total income | L16: =+SUM(L12:L15) -> 379659.6 | N16: 12,00,001 - 16,00,000 | P16: 0.15 | Q16: =+IF(R15>400000,400000,R15) -> 400000 | R16: =+IF(R15>400000,R15-400000,0) -> 785000 | S16: =+Q16*P16 -> 60000
B17: Income from Term deposits interest | C17: 50000 | D17: =+C17 -> 50000 | E17: =+C17 -> 50000 | G17: Less: Rebate u/s 87A for taxable income upto 5 lakhs (max. Rs. 12,500/-) | L17: =+IF(C7="RESIDENT",IF(D37<=500000,IF(L16>12500,0,L16),0),0) -> 0 | N17: 16,00,001 - 20,00,000 | P17: 0.2 | Q17: =+IF(R16>400000,400000,R16) -> 400000 | R17: =+IF(R16>400000,R16-400000,0) -> 385000 | S17: =+Q17*P17 -> 80000
B18: Income from other interest | C18: 5000 | D18: =+C18 -> 5000 | E18: =+C18 -> 5000 | N18: 20,00,001 - 24,00,000 | P18: 0.25 | Q18: =+IF(R17>400000,400000,R17) -> 385000 | R18: =+IF(R17>400000,R17-400000,0) -> 0 | S18: =+Q18*P18 -> 96250
B19: Rental Income received | C19: 300000 | D19: =+C19*0.7 -> 210000 | E19: =+C19*0.7 -> 210000 | G19: Tax after rebate | L19: =+L16-L17 -> 379659.6 | N19: Above 24,00,000 | P19: 0.3 | Q19: =+R18 -> 0 | S19: =+Q19*P19 -> 0
B20: Other Incomes other than income taxable at special rates | C20: 60000 | D20: =+C20 -> 60000 | E20: =+C20 -> 60000 | G20: Add: Surcharge | L20: =+IF(D37>50000000,L19*0.37,(IF(D37>20000000,L19*0.25,(IF(D37>10000000,L19*0.15,(IF(D37>5000000,L19*0.1,0))))))) -> 0 | N20: Tax on total income | S20: =+SUM(S13:S19) -> 296250
L21: =+IF((L19+L20)>(IF(D37>50000000,(D37-50000000+18515625),IF(D37>20000000,D37-20000000+6684375,IF(D37>10000000,D37-10000000+3093750,IF(D37>5000000,D37-5000000+1312500,0))))),(IF(D37>50000000,(D37-50000000+18515625),IF(D37>20000000,D37-20000000+6684375,IF(D37>10000000,D37-10000000+3093750,IF(D37>5000000,D37-5000000+1312500,0))))),0) -> 0
B22: Total Income other than income taxable at special rates | D22: =+SUM(D16:D20)+D13 -> 2840000 | E22: =+SUM(E16:E20)+E13 -> 2840000 | G22: Less: Marginal Relief for Surcharge | L22: =+IF(L21>0,L19+L20-L21,0) -> 0 | N22: Less: Rebate u/s 87A for taxable income upto 12 lakhs (max. Rs. 60,000/-) | S22: =IF(C7="RESIDENT",IF(E37>=1200000,(IF(S20>=(E37-1200000),(S20-(E37-1200000)),IF(S20>60000,0,S20))),IF(S20>60000,0,S20)),0) -> 0
B23: Less: Interest on Home Loan- Self Occupied | C23: 234234 | D23: =+IF((C23+C24-D19)>200000,200000+D19,(C23+C24)) -> 354234 | E23: NA | G23: Tax with surcharge | L23: =+L19+L20-L22 -> 379659.6 | N23: Tax after rebate | S23: =+S20-S22 -> 296250
B24: Less: Interest Home Loan - Let Out | C24: 120000 | E24: =+IF(C24-E19>0,E19,C24) -> 120000 | G24: Add: Cess @ 4% | L24: =+L23*0.04 -> 15186.384 | N24: Add: Surcharge | S24: =+IF(E37>20000000,S23*0.25,(IF(E37>10000000,S23*0.15,(IF(E37>5000000,S23*0.1,0))))) -> 0
S25: =+IF((S23+S24)>(IF(E37>20000000,E37-20000000+6417000,IF(E37>10000000,E37-10000000+2838000,IF(E37>5000000,E37-5000000+1080000,0)))),(IF(E37>20000000,E37-20000000+6417000,IF(E37>10000000,E37-10000000+2838000,IF(E37>5000000,E37-5000000+1080000,0)))),0) -> 0
B26: Less: HRA Exemption (refer HRA Calculator) | C26: 234 | D26: =+C26 -> 234 | E26: NA | G26: Total Tax Payable (Old Regime) | L26: =+L24+L23 -> 394845.98 | N26: Less: Marginal Relief for Surcharge | S26: =+IF(S25>0,S23+S24-S25,0) -> 0
B27: Less: Other Exempt allowances | D27: 110000 | E27: 80000 | N27: Tax with surcharge | S27: =+S23+S24-S26 -> 296250
B28: Less: 80C Deduction | C28: 180000 | D28: =+IF(C28>150000,150000,C28) -> 150000 | E28: NA | G28: =+IF(D41="NEW REGIME","NEW REGIME IS RECOMMENDED","OLD REGIME IS RECOMMENDED") -> NEW REGIME IS RECOMMENDED | N28: Add: Cess @ 4% | S28: =+S27*0.04 -> 11850
B29: Less: 80CCD(1B) – Employee’s contribution to NPS | C29: 60000 | D29: =+IF(C29>50000,50000,C29) -> 50000 | E29: NA | N29: Total Tax Payable (New Regime) | S29: =+S28+S27 -> 308100
B30: Less: 80CCD(2) – Employer’s NPS Contribution | D30: 150000 | E30: 180000
B31: Less: 80D – Health Insurance for Self | C31: 50000 | D31: =+IF(C6<60,IF(C31<25000,C31,25000),IF(C31<50000,C31,50000)) -> 25000 | E31: NA | N31: NOTES
B32: Less: 80D – Health Insurance for Parents | C32: 60000 | D32: =+IF(C8<60,IF(C32<25000,C32,25000),IF(C32<50000,C32,50000)) -> 50000 | E32: NA | N32: 1. Under the new tax regime, only interest on loan for let-out property is deductible, limited to the extent of taxable rental income. Technically interest will get nullified and any excess interest will not be carried forward/set-off with any other incomes
B33: Less: 80TTA – Interest from Savings Bank | D33: =+IF(C16>10000,10000,C16) -> 10000 | E33: NA | G33: Disclaimer: This calculator provides a quick and basic tax estimate for resident and non-resident individuals across all age groups, with income taxable at normal rates. It may not cover all scenarios. For accurate tax computation and return filing, please refer to the applicable Acts, Rules, and regulations.
B34: Less: 80TTB – Interest from Term deposits | D34: =+IF(C6>=60,(IF(C17>50000,50000,C17)),0) -> 0 | E34: NA | N34: 2. Employees can change the Tax Regime any time before filing of ITR for the year
B35: Less: Any other deductions not covered above | D35: 0 | E35: 0
B36: Total Exemptions and Deductions etc., | D36: =+D14+SUM(D23:D35) -> 949468 | E36: =+E14+SUM(E23:E35) -> 455000 | N36: 3. Rebate is not applicable for non-residents.
B37: Net Taxable Income | D37: =+IF((SUM(D15:D19)+D20-D23-SUM(D26:D35))>0,SUM(D15:D19)+D20-D23-SUM(D26:D35),0) -> 1890532 | E37: =+IF((SUM(E15:E19)+E20-E24-SUM(E26:E35))>0,SUM(E15:E19)+E20-E24-SUM(E26:E35),0) -> 2385000
B38: TAX AS PER OLD TAX REGIME | D38: =+L26 -> 394845.98
B39: TAX AS PER NEW TAX REGIME | D39: =+S29 -> 308100
B40: TAX SAVING BY CHOOSING | C40: =+IF(D38>D39,"NEW REGIME","OLD REGIME") -> NEW REGIME | D40: =ABS(+D38-D39) -> 86745.984
B41: WHICH REGIME IS BENEFICIAL | D41: =+IF(D38>D39,"NEW REGIME","OLD REGIME") -> NEW REGIME

Sheet Tax Summary
B4: Summary - FY 2025–2026 (AY 2026–2027)
J6: Total Income | N6: Taxable Income
K7: Old | L7: New | O7: Old | P7: New
K8: =+'Tax Calculator FY 2025-26'!D22 -> 2840000 | L8: =+'Tax Calculator FY 2025-26'!E22 -> 2840000 | O8: =+'Tax Calculator FY 2025-26'!D37 -> 1890532 | P8: =+'Tax Calculator FY 2025-26'!E37 -> 2385000
J11: Exemptions & Deductions
K12: Old | L12: New | N12: Tax Payable
K13: =+'Tax Calculator FY 2025-26'!D36 -> 949468 | L13: =+'Tax Calculator FY 2025-26'!E36 -> 455000 | O13: =+IF(O14>P14,"Old","Old (Recommended)") -> Old | P13: =+IF(O14>=P14,"New (Recommended)","New") -> New (Recommended)
O14: =+'Tax Calculator FY 2025-26'!D38 -> 394845.98 | P14: =+'Tax Calculator FY 2025-26'!D39 -> 308100
J15: Exempt Allowances | K15: =+'Tax Calculator FY 2025-26'!D26+'Tax Calculator FY 2025-26'!D27 -> 110234 | L15: =+'Tax Calculator FY 2025-26'!E27 -> 80000
N16: Income tax | O16: =+'Tax Calculator FY 2025-26'!L19 -> 379659.6 | P16: =+'Tax Calculator FY 2025-26'!S23 -> 296250
J17: Standard Deductions | K17: =+'Tax Calculator FY 2025-26'!D14 -> 50000 | L17: =+'Tax Calculator FY 2025-26'!E14 -> 75000
N18: Surcharge | O18: =+'Tax Calculator FY 2025-26'!L20-'Tax Calculator FY 2025-26'!L22 -> 0 | P18: =+'Tax Calculator FY 2025-26'!S24-'Tax Calculator FY 2025-26'!S26 -> 0
J19: Chapter VI A Deductions | K19: =+SUM('Tax Calculator FY 2025-26'!D28:D35) -> 435000 | L19: =+SUM('Tax Calculator FY 2025-26'!E28:E35) -> 180000
N20: Health and education cess | O20: =+'Tax Calculator FY 2025-26'!L24 -> 15186.384 | P20: =+'Tax Calculator FY 2025-26'!S28 -> 11850
J21: Home Loan Interest | K21: =+SUM('Tax Calculator FY 2025-26'!D23:D24) -> 354234 | L21: =+'Tax Calculator FY 2025-26'!E24 -> 120000
K25: =+IF(O14>P14,"New Tax Regime is recommended for you. It would save you","Old Tax Regime* is recommended for you. It would save you") -> New Tax Regime is recommended for you. It would save you | O25: =+ABS(O14-P14) -> 86745.984 | P25: in taxes.
K26: *To opt for the old tax regime, the ITR must be filed on or before 31st July 2026 (subject to change). If not filed within this deadline, only the new tax regime will be allowed.
K35: Old Regime | L35: New Regime
J36: Total Income | K36: =+K8 -> 2840000 | L36: =+L8 -> 2840000
J37: Deductions | K37: =+K13 -> 949468 | L37: =+L13 -> 455000
J38: Taxable income | K38: =+O8 -> 1890532 | L38: =+P8 -> 2385000
J39: Tax Payable | K39: =+O14 -> 394845.98 | L39: =+P14 -> 308100

Sheet HRA Calculator
B4: HRA Exemption Calculator
B6: Particulars | C6: Annually
B7: Basic + DA | C7: 600000
B8: HRA Received | C8: 540000
B9: Rent Paid | C9: 624000
B10: Are you Living in Any of the Below Metro Cities such as Delhi, Mumbai, Chennai and Kolkata? | C10: No
B11: Actual HRA Received | C11: =+C8 -> 540000
B12: Basic + DA (50% in Metro, 40% in Non Metro) | C12: =+IF(C10="Yes",C7*0.5,C7*0.4) -> 240000
B13: Actual Rent Paid minus 10% of (Basic + DA) | C13: =+C9-0.1*C7 -> 564000
B14: HRA Exemption | C14: =+MIN(C11,C12,C13) -> 240000
B16: TDS to be deducted for the year @2% (refer notes) | C16: =+IF(C9/12>50000,(C9*0.02),0) -> 12480
B18: ⚠️ Important: If you’re paying monthly house rent above ₹50,000, be aware — the Income Tax Department is sending notices for non-compliance. As per Section 194-IB of the Income Tax Act, 👉 If you’re an individual or HUF (not in business or audit), 👉 And you pay rent more than ₹50,000 per month, 👉 Then you must deduct TDS @2% and deposit it with the government.

Sheet New Regime Benefits
C3: Tax benefits under new tax regime: FY 2025-26 / AY 2026-27
C4: Deductions:
C5: 1. Salary Income: Standard deduction up to Rs 75,000
C6: 2. Family Pension: Standard deduction up to ₹25,000 or 1/3rd of pension, whichever is lower.
C7: 3. Home Loan interest u/s 24b only on Let-out property limited to the extent of taxable rental income. Technically interest will get nullified and any excess interest will not be carried forward/set-off with any other incomes.
C8: 4. Employer's contribution to NPS to the extent of 14% of basic salary. However, there is a threshold limit of Rs 7,50,000 on the overall contribution done by the employer towards NPS, PF and superannuation combined. Any excess amount will be taxable.
C9: 5.All contributions to Agniveer Corpus Fund (section 80CCH)
C10: 6. Default Regime: Starting from FY 2023-24, the new income tax regime will be set as the default option. If you want to continue using the old regime, you must submit the income tax return along with Form 10-IEA before the due date. You will have the option to switch between the two regimes annually to check the tax benefits.
C12: Exemptions:
C13: 1. Exemption on leave encashment is available under the new tax regime, the exemption threshold is ₹25 lakhs for non-government employees, at the time of retirement, leave encashment of up to ₹25 lakhs is tax-free under Section 10(10AA).

Sheet Old Regime Benefits
A4: Section | B4: No | C4: Type of Investment | D4: Proofs to be submitted by an employee | E4: Remarks
A5: E X E M P T I O N U N D E R S E C T I O N 80C | B5: 1 | C5: Life Insurance Premium | D5: a. Employee needs to Submit paid Life Insurance Premium receipts for Self, Spouse and Childrens for the F.Y.25-26. b. If employees name is not there on Life Insurance Receipts, employee is required to submit the letter, stating that these premiums are paid by myself and my spouse is not claiming the same for tax exemption. If any queries raised by Income Tax Department or any other Departments then Just Dial will not be responsible. U/s 80C of the Income Tax Act, Insurance premium cannot exceed the maximum ceiling given below: If policy is taken before 1/4/2012 – 20% of sum assured If policy is taken after 1/4/2012- 10% of sum assured *In case policy is taken on life of a person with disability or life of a person suffering from disease or ailment as given in section 80DDB and policy is taken after 1/4/2013 – 15% of sum assured. | E5: E X E M P T I O N Upto Rs. 1,50,000/- ( One Lakh Fifty Thousand Only )
B6: =B5+1 -> 2 | C6: Deferred annuity / Annuity plan | D6: Paid Premium receipts for the F.Y.25-26.
B7: =B6+1 -> 3 | C7: Public Provident Fund | D7: a. PPF Passbook duly stamped by respective Banks for the F.Y.25-26. b. Payment Receipts for the F.Y.25-26. will be accepted. C. In Case Passbook not available then employee has to provide the copy of Screenshot of Online Passbook.
B8: =B7+1 -> 4 | C8: National Savings Certificates (VIII Issue) | D8: Certificate towards Investment in NSC for the F.Y.25-26.
B9: =B8+1 -> 5 | C9: Unit-linked Insurance Plan | D9: Only paid Premium receipts for the F.Y.25-26.
B10: =B9+1 -> 6 | C10: Mutual Fund Investment | D10: The statement of Tax Saving Mutual Fund for the F.Y.25-26.
B11: =B10+1 -> 7 | C11: Tuition fees | D11: Tution Fees receipts along with School's Stamp affixed ( only Tuition Fees are allowed for exemption ).
B12: =B11+1 -> 8 | C12: Repayment of Principal amount of Housing Loan or Stamp Duty | D12: a.Housing Loan Certificate showing breakup of principal and interest amount, received from Bank for the F.Y.25-26. b. Possession Letter received for 1st Owner C. Sale Purchase aggrement for 2nd Owner
B13: =B12+1 -> 9 | C13: Five Years Term Deposit / Time Deposit | D13: Term/Fix Deposit Receipt provided by Schdeule Bank towards investment made in F.Y.22-23.
B14: =B13+1 -> 10 | C14: Pension scheme of Central Government. | D14: Receipts of payments.
B15: =B14+1 -> 11 | C15: Sukanya Samriddhi Scheme | D15: Passbook duly stamped by respective Banks for the F.Y.25-26.
B16: =B15+1 -> 12 | C16: Pension fund set up by any Mutual Fund | D16: Receipts of contibution made in such funds / Statement of accounts
B17: =B16+1 -> 13 | C17: Public Deposit Scheme of HUDCO | D17: Receipts of payments / Deposit Certificate
... B20: =B19+1 -> 16 | C20: Deposit in Senior Citizens Savings Scheme | D20: Deposite Certificate
A21: 80 CCC | B21: =B20+1 -> 17 | C21: Pension Fund for any annuity plan | D21: Paid Premium receipts for the F.Y.25-26.
A22: 80CCD | B22: =B21+1 -> 18 | C22: NPS-New Pension Scheme & Atal Pension Yojna | D22: Receipts of payments. Maximum exemption 10% of Salary
A23: 80CCD(1B) | B23: =B22+1 -> 19 | C23: NPS-New Pension Scheme & Atal Pension Yojna | D23: Additional contribution upto Rs. 50,000 will be allowable as deduction.(no deduction under this sub-section shall be allowed in respect of the amount on which a deduction has been claimed and allowed under sub-section (1) of Section 80CCD)
B24: =B23+1 -> 20
A25: 80 U | C25: Person with disability | D25: Ceritificate of disability issued by Government Authority.
D26: Employee will get the exemption only on submission of Disability Certificate from Medical Authority in Form 10-IA :-
D27: 1 ) Up to Rs.75,000 if disability is over 40%
D28: 2 ) Rs.1,25,000 if disability is severe and is more than 80%. As per certificate
A30: 80 D | B30: 21 | C30: Medical Insurance Premium | D30: Receipts and Certificate issued by various Mediclaim companies.
D31: - for an employee and his/her spouse, dependent children Rs. 25000/- ( Rs 50,000/- in case of employee/spouse/dependent children being 60 years old & above) Additional Deduction: - for an employee's parent(s) Rs. 25000/- ( Rs 50,000/- in case of 60 years old & above) Note: In case of single premium health insurance policies having cover of more than one year, the deduction shall be allowed on proportionate basis for the number of years for which health insurance cover is provided, subject to the specified monetary limit. Further, deduction for a preventive health check up up to Rs. 5,000 will be available u/s 80D. However, it is subsumed within overall limit of section 80D
A33: 80 DD | B33: 22 | C33: Maintenance of a dependant person with disability | D33: Employee will get the exemption only on submission of Disability Certificate of the Dependent person with disability obtained from Medical Authority in Form 10-I :-
D34: Exemption will be lower of following :-
D35: 1 ) Up to Rs.75,000 if disability is over 40% to 80%
D36: 2 ) Rs.1,25,000 if disability is severe i.e. over 80%. As per certificate
A38: 80 DDB | B38: 23 | C38: Medical Treatment for specified disease or ailment | D38: Employee will get the exemption only on submission of Form 10-I obtained from Medical Authority :-
D39: Exemption will be lower of following :-
D40: For less than 60 years old - Lower of Rs 40,000 or the amount actually paid For more than 60 years old - Lower of Rs 1,00,000 or the amount actually paid
A42: 80 E | B42: 24 | C42: Payment of Interest on loan taken for higher education | D42: 1 ) Certificate of completion of Higher Studies.
D43: 2 ) Loan Certificate received from Bank.
D44: Amount paid by Employee during the financial year on loan taken for higher education of employee, Amount is exempted will be entire amount of interest ( for 1st year in which the assessee starts paying the interest + 7 Years or till interest paid in full, whichever is earlier)
B45: 25
A46: 80EE | C46: Payment of Interest on home loan taken in FY 2016-17 for first time home owners | D46: Interest Payable Certificate received from Bank for the F.Y.25-26. | E46: An additional deduction of Rs 50,000 can be claimed on home loan interest. This is in addition to deduction of Rs 2,00,000 allowed under section 24 of the Income Tax Act for a self-occupied house property.
D47: The deduction under this section is available only to an individual who is a first time home owner. The value of the property purchased must be less than Rs 50 lakh and the home loan must be less than Rs 35 lakh. The loan must be taken from a financial institution and must have been sanctioned between 01.04.2016 to 31.03.2017
D48: If you’re claiming this deduction in FY 2016-17, then you can continue to claim this deduction till the loan is repaid. No Deduction for loan sanctioned after FY 2016-17.
A51: 10(13A) | B51: 26 | C51: HRA - Rent Receipts | D51: Monthly Or Quarterly Rent Receipts along with pan card no of the lanlord for rent above Rs.100,000/- p.a. or Rs. 8,333/- p.m.
...
